<?xml version="1.0" encoding="utf-8"?>
<!-- This URDF was automatically created by SolidWorks to URDF Exporter! Originally created by Stephen Brawner (brawner@gmail.com) 
     Commit Version: 1.6.0-4-g7f85cfe  Build Version: 1.6.7995.38578
     For more information, please see http://wiki.ros.org/sw_urdf_exporter -->
<robot
  name="Assem10_visual">
  <link
    name="base_link">
    <inertial>
      <origin
        xyz="-0.00717647369148372 0.271968313486189 0.0414876608737963"
        rpy="0 0 0" />
      <mass
        value="0.0324330072355437" />
      <inertia
        ixx="8.63564187395702E-06"
        ixy="1.21514277699486E-08"
        ixz="7.76541280328129E-07"
        iyy="5.58034114676458E-06"
        iyz="-5.09153879016956E-08"
        izz="5.56720479179505E-06" />
    </inertial>
    <visual>
      <origin
        xyz="0 0 0"
        rpy="0 0 0" />
      <geometry>
        <mesh
          filename="package://Assem10_visual/meshes/base_link.STL" />
      </geometry>
      <material
        name="">
        <color
          rgba="0.792156862745098 0.819607843137255 0.933333333333333 1" />
      </material>
    </visual>
    <collision>
      <origin
        xyz="0 0 0"
        rpy="0 0 0" />
      <geometry>
        <mesh
          filename="package://Assem10_visual/meshes/base_link.STL" />
      </geometry>
    </collision>
  </link>
  <link
    name="hip_Link">
    <inertial>
      <origin
        xyz="0.00180731276160201 -0.00836164741344506 0.000442740481063931"
        rpy="0 0 0" />
      <mass
        value="0.00819252451340341" />
      <inertia
        ixx="9.85683698113486E-07"
        ixy="1.24210912093877E-21"
        ixz="6.03637825618391E-09"
        iyy="8.56823450328505E-07"
        iyz="-5.36643675329181E-21"
        izz="9.57527130390923E-07" />
    </inertial>
    <visual>
      <origin
        xyz="0 0 0"
        rpy="0 0 0" />
      <geometry>
        <mesh
          filename="package://Assem10_visual/meshes/hip_Link.STL" />
      </geometry>
      <material
        name="">
        <color
          rgba="0.752941176470588 0.752941176470588 0.752941176470588 1" />
      </material>
    </visual>
    <collision>
      <origin
        xyz="0 0 0"
        rpy="0 0 0" />
      <geometry>
        <mesh
          filename="package://Assem10_visual/meshes/hip_Link.STL" />
      </geometry>
    </collision>
  </link>
  <joint
    name="hip_joint"
    type="revolute">
    <origin
      xyz="-0.0049045 0.2422 0.031968"
      rpy="0 0 0" />
    <parent
      link="base_link" />
    <child
      link="hip_Link" />
    <axis
      xyz="0 1 0" />
    <limit
      lower="-1.571"
      upper="1.571"
      effort="0.055"
      velocity="5.82" />
  </joint>
  <link
    name="thigh_Link">
    <inertial>
      <origin
        xyz="0.0246318254408482 -0.0180431075132355 0.00588664528558094"
        rpy="0 0 0" />
      <mass
        value="0.0474577407114943" />
      <inertia
        ixx="8.8598638302836E-06"
        ixy="-5.09345436720843E-08"
        ixz="-8.02343009959709E-07"
        iyy="6.98674583183772E-06"
        iyz="-1.20711636644903E-08"
        izz="1.20297809514324E-05" />
    </inertial>
    <visual>
      <origin
        xyz="0 0 0"
        rpy="0 0 0" />
      <geometry>
        <mesh
          filename="package://Assem10_visual/meshes/thigh_Link.STL" />
      </geometry>
      <material
        name="">
        <color
          rgba="0.752941176470588 0.752941176470588 0.752941176470588 1" />
      </material>
    </visual>
    <collision>
      <origin
        xyz="0 0 0"
        rpy="0 0 0" />
      <geometry>
        <mesh
          filename="package://Assem10_visual/meshes/thigh_Link.STL" />
      </geometry>
    </collision>
  </link>
  <joint
    name="thigh_joint"
    type="revolute">
    <origin
      xyz="-0.018838 -0.02734 -0.0044773"
      rpy="0 0 0" />
    <parent
      link="hip_Link" />
    <child
      link="thigh_Link" />
    <axis
      xyz="0.97268 0 0.23214" />
    <limit
      lower="0"
      upper="1.0472"
      effort="0.055"
      velocity="5.82" />
  </joint>
  <link
    name="leg_Link">
    <inertial>
      <origin
        xyz="-0.0285787935419678 -0.0129129269095195 -0.0031919559235554"
        rpy="0 0 0" />
      <mass
        value="0.0582940676653252" />
      <inertia
        ixx="2.74025472650784E-05"
        ixy="5.69416800838094E-07"
        ixz="-5.25835103236541E-07"
        iyy="9.05897383508179E-06"
        iyz="-2.16042458059863E-06"
        izz="2.94803397806849E-05" />
    </inertial>
    <visual>
      <origin
        xyz="0 0 0"
        rpy="0 0 0" />
      <geometry>
        <mesh
          filename="package://Assem10_visual/meshes/leg_Link.STL" />
      </geometry>
      <material
        name="">
        <color
          rgba="0.752941176470588 0.752941176470588 0.752941176470588 1" />
      </material>
    </visual>
    <collision>
      <origin
        xyz="0 0 0"
        rpy="0 0 0" />
      <geometry>
        <mesh
          filename="package://Assem10_visual/meshes/leg_Link.STL" />
      </geometry>
    </collision>
  </link>
  <joint
    name="leg_joint"
    type="revolute">
    <origin
      xyz="0.052517 -0.09411 0.01257"
      rpy="0 0 0" />
    <parent
      link="thigh_Link" />
    <child
      link="leg_Link" />
    <axis
      xyz="0.97268 0 0.23214" />
    <limit
      lower="-0.523"
      upper="1.0472"
      effort="0.055"
      velocity="5.82" />
  </joint>
  <link
    name="foot1_Link">
    <inertial>
      <origin
        xyz="-0.0291713766534113 0.00793930538079669 0.00101307844970946"
        rpy="0 0 0" />
      <mass
        value="0.0349573612548581" />
      <inertia
        ixx="5.7724859476221E-06"
        ixy="5.19624692095542E-08"
        ixz="6.24686798600047E-21"
        iyy="5.50484351057989E-06"
        iyz="-2.59767799566153E-20"
        izz="9.07608897611531E-06" />
    </inertial>
    <visual>
      <origin
        xyz="0 0 0"
        rpy="0 0 0" />
      <geometry>
        <mesh
          filename="package://Assem10_visual/meshes/foot1_Link.STL" />
      </geometry>
      <material
        name="">
        <color
          rgba="0.752941176470588 0.752941176470588 0.752941176470588 1" />
      </material>
    </visual>
    <collision>
      <origin
        xyz="0 0 0"
        rpy="0 0 0" />
      <geometry>
        <mesh
          filename="package://Assem10_visual/meshes/foot1_Link.STL" />
      </geometry>
    </collision>
  </link>
  <joint
    name="foot1_joint"
    type="revolute">
    <origin
      xyz="0.0015755 -0.092752 -0.0066013"
      rpy="0 -0.23428 0" />
    <parent
      link="leg_Link" />
    <child
      link="foot1_Link" />
    <axis
      xyz="1 0 0" />
    <limit
      lower="0"
      upper="0.523"
      effort="0.055"
      velocity="5.83" />
  </joint>
  <link
    name="foot2_Link">
    <inertial>
      <origin
        xyz="0.0011633 -0.0060341 -0.00017497"
        rpy="0 0 0" />
      <mass
        value="0.055753" />
      <inertia
        ixx="2.3892E-05"
        ixy="-1.2524E-08"
        ixz="2.7681E-06"
        iyy="2.7648E-05"
        iyz="5.0827E-08"
        izz="1.3087E-05" />
    </inertial>
    <visual>
      <origin
        xyz="0 0 0"
        rpy="0 0 0" />
      <geometry>
        <mesh
          filename="package://Assem10_visual/meshes/foot2_Link.STL" />
      </geometry>
      <material
        name="">
        <color
          rgba="0.75294 0.75294 0.75294 1" />
      </material>
    </visual>
    <collision>
      <origin
        xyz="0 0 0"
        rpy="0 0 0" />
      <geometry>
        <mesh
          filename="package://Assem10_visual/meshes/foot2_Link.STL" />
      </geometry>
    </collision>
  </link>
  <joint
    name="foot2_joint"
    type="revolute">
    <origin
      xyz="-0.017637 -0.092752 -0.032262"
      rpy="0 0 0" />
    <parent
      link="leg_Link" />
    <child
      link="foot2_Link" />
    <axis
      xyz="-0.23214 0 0.97268" />
    <limit
      lower="-1.57"
      upper="1.57"
      effort="0.055"
      velocity="5.83" />
  </joint>
</robot>