<?xml version="1.0" encoding="utf-8"?>
<!-- This URDF was automatically created by SolidWorks to URDF Exporter! Originally created by Stephen Brawner (brawner@gmail.com) 
     Commit Version: 1.6.0-4-g7f85cfe  Build Version: 1.6.7995.38578
     For more information, please see http://wiki.ros.org/sw_urdf_exporter -->
<robot
  name="Robot_collision">
  <link
    name="base_link">
    <inertial>
      <origin
        xyz="0.040200501273785 0.330749999999998 0.0339464997878695"
        rpy="0 0 0" />
      <mass
        value="0.86652" />
      <inertia
        ixx="0.00104401218"
        ixy="1.34300526833756E-18"
        ixz="-7.86046575051991E-20"
        iyy="0.00158638149"
        iyz="-5.62429876976855E-20"
        izz="0.00153727869" />
    </inertial>
    <visual>
      <origin
        xyz="0 0 0"
        rpy="0 0 0" />
      <geometry>
        <mesh
          filename="package://Robot_collision/meshes/base_link.STL" />
      </geometry>
      <material
        name="">
        <color
          rgba="0.792156862745098 0.819607843137255 0.933333333333333 1" />
      </material>
    </visual>
    <collision>
      <origin
        xyz="0 0 0"
        rpy="0 0 0" />
      <geometry>
        <mesh
          filename="package://Robot_collision/meshes/base_link.STL" />
      </geometry>
    </collision>
  </link>
  <link
    name="hip_link">
    <inertial>
      <origin
        xyz="0.000499999999641676 0.0220625073400544 0.00708396946565209"
        rpy="0 0 0" />
      <mass
        value="0.19587170304" />
      <inertia
        ixx="0.000119707692348043"
        ixy="1.53685598264586E-19"
        ixz="-1.15777603621505E-20"
        iyy="6.67796077184976E-05"
        iyz="-6.01848431217352E-06"
        izz="7.49962965053851E-05" />
    </inertial>
    <visual>
      <origin
        xyz="0 0 0"
        rpy="0 0 0" />
      <geometry>
        <mesh
          filename="package://Robot_collision/meshes/hip_link.STL" />
      </geometry>
      <material
        name="">
        <color
          rgba="0.76078431372549 0.4 0.180392156862745 0.3" />
      </material>
    </visual>
    <collision>
      <origin
        xyz="0 0 0"
        rpy="0 0 0" />
      <geometry>
        <mesh
          filename="package://Robot_collision/meshes/hip_link.STL" />
      </geometry>
    </collision>
  </link>
  <joint
    name="hip_joint"
    type="revolute">
    <origin
      xyz="0.0026505 0.24245 0.025446"
      rpy="0 0 0" />
    <parent
      link="base_link" />
    <child
      link="hip_link" />
    <axis
      xyz="0 1 0" />
    <limit
      lower="0"
      upper="3.14"
      effort="0.505"
      velocity="8.702" />
  </joint>
  <link
    name="thigh_link">
    <inertial>
      <origin
        xyz="0.027085 -0.019807 3.5486E-05"
        rpy="0 0 0" />
      <mass
        value="0.099404" />
      <inertia
        ixx="5.0024E-05"
        ixy="2.8227E-07"
        ixz="-2.7819E-20"
        iyy="2.9494E-05"
        iyz="-2.3961E-20"
        izz="6.9163E-05" />
    </inertial>
    <visual>
      <origin
        xyz="0 0 0"
        rpy="0 0 0" />
      <geometry>
        <mesh
          filename="package://Robot_collision/meshes/thigh_link.STL" />
      </geometry>
      <material
        name="">
        <color
          rgba="0.76078 0.4 0.18039 0.3" />
      </material>
    </visual>
    <collision>
      <origin
        xyz="0 0 0"
        rpy="0 0 0" />
      <geometry>
        <mesh
          filename="package://Robot_collision/meshes/thigh_link.STL" />
      </geometry>
    </collision>
  </link>
  <joint
    name="thigh_joint"
    type="revolute">
    <origin
      xyz="-0.019363 -0.02734 1.8014E-05"
      rpy="0 0 0" />
    <parent
      link="hip_link" />
    <child
      link="thigh_link" />
    <axis
      xyz="1 0 0" />
    <limit
      lower="0"
      upper="1.047"
      effort="0.505"
      velocity="8.72" />
  </joint>
  <link
    name="leg_link">
    <inertial>
      <origin
        xyz="-0.027 -0.012318 0.0055555"
        rpy="0 0 0" />
      <mass
        value="0.23259" />
      <inertia
        ixx="0.00025819"
        ixy="2.4859E-19"
        ixz="3.584E-20"
        iyy="0.00010163"
        iyz="-2.8184E-20"
        izz="0.00028132" />
    </inertial>
    <visual>
      <origin
        xyz="0 0 0"
        rpy="0 0 0" />
      <geometry>
        <mesh
          filename="package://Robot_collision/meshes/leg_link.STL" />
      </geometry>
      <material
        name="">
        <color
          rgba="0.76078 0.4 0.18039 0.3" />
      </material>
    </visual>
    <collision>
      <origin
        xyz="0 0 0"
        rpy="0 0 0" />
      <geometry>
        <mesh
          filename="package://Robot_collision/meshes/leg_link.STL" />
      </geometry>
    </collision>
  </link>
  <joint
    name="leg_joint"
    type="revolute">
    <origin
      xyz="0.054 -0.09411 3.5486E-05"
      rpy="0 0 0" />
    <parent
      link="thigh_link" />
    <child
      link="leg_link" />
    <axis
      xyz="1 0 0" />
    <limit
      lower="0"
      upper="1.047"
      effort="0.505"
      velocity="8.72" />
  </joint>
  <link
    name="foot1_Link">
    <inertial>
      <origin
        xyz="-0.025624 -0.00076548 0.0087695"
        rpy="0 0 0" />
      <mass
        value="0.12238" />
      <inertia
        ixx="8.3422E-05"
        ixy="2.7296E-06"
        ixz="-1.1765E-06"
        iyy="5.4178E-05"
        iyz="7.9807E-06"
        izz="8.0648E-05" />
    </inertial>
    <visual>
      <origin
        xyz="0 0 0"
        rpy="0 0 0" />
      <geometry>
        <mesh
          filename="package://Robot_collision/meshes/foot1_Link.STL" />
      </geometry>
      <material
        name="">
        <color
          rgba="0.76078 0.4 0.18039 0.3" />
      </material>
    </visual>
    <collision>
      <origin
        xyz="0 0 0"
        rpy="0 0 0" />
      <geometry>
        <mesh
          filename="package://Robot_collision/meshes/foot1_Link.STL" />
      </geometry>
    </collision>
  </link>
  <joint
    name="foot1_joint"
    type="revolute">
    <origin
      xyz="0 -0.093 0"
      rpy="0 0 0" />
    <parent
      link="leg_link" />
    <child
      link="foot1_Link" />
    <axis
      xyz="1 0 0" />
    <limit
      lower="0"
      upper="0.523"
      effort="0.505"
      velocity="8.72" />
  </joint>
  <link
    name="foot2_Link">
    <inertial>
      <origin
        xyz="0.00085707 0.004447 -0.023337"
        rpy="0 0 0" />
      <mass
        value="0.082046" />
      <inertia
        ixx="4.3876E-05"
        ixy="1.5084E-21"
        ixz="-5.288E-22"
        iyy="1.9879E-05"
        iyz="2.593E-21"
        izz="3.3966E-05" />
    </inertial>
    <visual>
      <origin
        xyz="0 0 0"
        rpy="0 0 0" />
      <geometry>
        <mesh
          filename="package://Robot_collision/meshes/foot2_Link.STL" />
      </geometry>
      <material
        name="">
        <color
          rgba="0.76078 0.4 0.18039 0.3" />
      </material>
    </visual>
    <collision>
      <origin
        xyz="0 0 0"
        rpy="0 0 0" />
      <geometry>
        <mesh
          filename="package://Robot_collision/meshes/foot2_Link.STL" />
      </geometry>
    </collision>
  </link>
  <joint
    name="foot2_joint"
    type="revolute">
    <origin
      xyz="-0.024645 -0.093 -0.0205"
      rpy="0 0 0" />
    <parent
      link="leg_link" />
    <child
      link="foot2_Link" />
    <axis
      xyz="0 0 1" />
    <limit
      lower="0"
      upper="3.14"
      effort="0.505"
      velocity="8.72" />
  </joint>
  <link
    name="hip2_Link">
    <inertial>
      <origin
        xyz="0.000499999999997981 0.019062507339988 0.00708396946564897"
        rpy="0 0 0" />
      <mass
        value="0.19587170304" />
      <inertia
        ixx="0.000119707692348043"
        ixy="1.51652719191175E-19"
        ixz="-1.15777603621505E-20"
        iyy="6.67796077184976E-05"
        iyz="-6.01848431217352E-06"
        izz="7.49962965053851E-05" />
    </inertial>
    <visual>
      <origin
        xyz="0 0 0"
        rpy="0 0 0" />
      <geometry>
        <mesh
          filename="package://Robot_collision/meshes/hip2_Link.STL" />
      </geometry>
      <material
        name="">
        <color
          rgba="0.76078431372549 0.4 0.180392156862745 0.3" />
      </material>
    </visual>
    <collision>
      <origin
        xyz="0 0 0"
        rpy="0 0 0" />
      <geometry>
        <mesh
          filename="package://Robot_collision/meshes/hip2_Link.STL" />
      </geometry>
    </collision>
  </link>
  <joint
    name="hip2_joint"
    type="revolute">
    <origin
      xyz="0.077751 0.24545 0.025446"
      rpy="0 0 0" />
    <parent
      link="base_link" />
    <child
      link="hip2_Link" />
    <axis
      xyz="0 1 0" />
    <limit
      lower="0"
      upper="3.142"
      effort="0.505"
      velocity="8.72" />
  </joint>
  <link
    name="thigh2_Link">
    <inertial>
      <origin
        xyz="-0.026915 -0.019807 3.5486E-05"
        rpy="0 0 0" />
      <mass
        value="0.099404" />
      <inertia
        ixx="5.0024E-05"
        ixy="2.8227E-07"
        ixz="-2.8205E-20"
        iyy="2.9494E-05"
        iyz="-2.033E-20"
        izz="6.9163E-05" />
    </inertial>
    <visual>
      <origin
        xyz="0 0 0"
        rpy="0 0 0" />
      <geometry>
        <mesh
          filename="package://Robot_collision/meshes/thigh2_Link.STL" />
      </geometry>
      <material
        name="">
        <color
          rgba="0.76078 0.4 0.18039 0.3" />
      </material>
    </visual>
    <collision>
      <origin
        xyz="0 0 0"
        rpy="0 0 0" />
      <geometry>
        <mesh
          filename="package://Robot_collision/meshes/thigh2_Link.STL" />
      </geometry>
    </collision>
  </link>
  <joint
    name="thigh2_joint"
    type="revolute">
    <origin
      xyz="0.034637 -0.03034 1.8014E-05"
      rpy="0 0 0" />
    <parent
      link="hip2_Link" />
    <child
      link="thigh2_Link" />
    <axis
      xyz="1 0 0" />
    <limit
      lower="0"
      upper="1.047"
      effort="0.505"
      velocity="8.72" />
  </joint>
  <link
    name="leg_Link">
    <inertial>
      <origin
        xyz="-0.027 -0.0122211946789355 0.0057648584745762"
        rpy="0 0 0" />
      <mass
        value="0.232589231399242" />
      <inertia
        ixx="0.000258193356797934"
        ixy="4.5286846446105E-19"
        ixz="3.05451598070012E-20"
        iyy="0.000101680881915206"
        iyz="3.06595490531911E-06"
        izz="0.000281270719740036" />
    </inertial>
    <visual>
      <origin
        xyz="0 0 0"
        rpy="0 0 0" />
      <geometry>
        <mesh
          filename="package://Robot_collision/meshes/leg_Link.STL" />
      </geometry>
      <material
        name="">
        <color
          rgba="0.76078431372549 0.4 0.180392156862745 0.3" />
      </material>
    </visual>
    <collision>
      <origin
        xyz="0 0 0"
        rpy="0 0 0" />
      <geometry>
        <mesh
          filename="package://Robot_collision/meshes/leg_Link.STL" />
      </geometry>
    </collision>
  </link>
  <joint
    name="leg_joint"
    type="revolute">
    <origin
      xyz="0 -0.09411 3.5486E-05"
      rpy="0 0 0" />
    <parent
      link="thigh2_Link" />
    <child
      link="leg_Link" />
    <axis
      xyz="-1 0 0" />
    <limit
      lower="0"
      upper="0.523"
      effort="0.505"
      velocity="8.72" />
  </joint>
  <link
    name="foot3_Link">
    <inertial>
      <origin
        xyz="-0.025624 -0.00076548 0.0087695"
        rpy="0 0 0" />
      <mass
        value="0.12238" />
      <inertia
        ixx="8.3422E-05"
        ixy="2.7296E-06"
        ixz="-1.1765E-06"
        iyy="5.4178E-05"
        iyz="7.9807E-06"
        izz="8.0648E-05" />
    </inertial>
    <visual>
      <origin
        xyz="0 0 0"
        rpy="0 0 0" />
      <geometry>
        <mesh
          filename="package://Robot_collision/meshes/foot3_Link.STL" />
      </geometry>
      <material
        name="">
        <color
          rgba="0.76078 0.4 0.18039 0.3" />
      </material>
    </visual>
    <collision>
      <origin
        xyz="0 0 0"
        rpy="0 0 0" />
      <geometry>
        <mesh
          filename="package://Robot_collision/meshes/foot3_Link.STL" />
      </geometry>
    </collision>
  </link>
  <joint
    name="foot3_joint"
    type="revolute">
    <origin
      xyz="0 -0.092986 0.001587"
      rpy="0 0 0" />
    <parent
      link="leg_Link" />
    <child
      link="foot3_Link" />
    <axis
      xyz="1 0 0" />
    <limit
      lower="0"
      upper="0.523"
      effort="0.505"
      velocity="8.72" />
  </joint>
  <link
    name="foot4_Link">
    <inertial>
      <origin
        xyz="-0.0011429 0.004447 -0.023463"
        rpy="0 0 0" />
      <mass
        value="0.082046" />
      <inertia
        ixx="4.3876E-05"
        ixy="3.1992E-21"
        ixz="-6.5891E-22"
        iyy="1.9879E-05"
        iyz="2.0801E-21"
        izz="3.3966E-05" />
    </inertial>
    <visual>
      <origin
        xyz="0 0 0"
        rpy="0 0 0" />
      <geometry>
        <mesh
          filename="package://Robot_collision/meshes/foot4_Link.STL" />
      </geometry>
      <material
        name="">
        <color
          rgba="0.76078 0.4 0.18039 0.3" />
      </material>
    </visual>
    <collision>
      <origin
        xyz="0 0 0"
        rpy="0 0 0" />
      <geometry>
        <mesh
          filename="package://Robot_collision/meshes/foot4_Link.STL" />
      </geometry>
    </collision>
  </link>
  <joint
    name="foot4_joint"
    type="revolute">
    <origin
      xyz="-0.024645 -0.092986 -0.018913"
      rpy="0 0 0" />
    <parent
      link="leg_Link" />
    <child
      link="foot4_Link" />
    <axis
      xyz="0 0 -1" />
    <limit
      lower="0"
      upper="3.14"
      effort="0.505"
      velocity="8.72" />
  </joint>
  <link
    name="neck_Link">
    <inertial>
      <origin
        xyz="-0.0136499999996535 0.0188858848752946 -0.01022120331409"
        rpy="0 0 0" />
      <mass
        value="0.0953994161289136" />
      <inertia
        ixx="3.85007818200498E-05"
        ixy="-2.7259743518364E-19"
        ixz="-1.16857291488913E-18"
        iyy="5.54533196571283E-05"
        iyz="1.39930293196946E-05"
        izz="7.24844147837779E-05" />
    </inertial>
    <visual>
      <origin
        xyz="0 0 0"
        rpy="0 0 0" />
      <geometry>
        <mesh
          filename="package://Robot_collision/meshes/neck_Link.STL" />
      </geometry>
      <material
        name="">
        <color
          rgba="0.792156862745098 0.819607843137255 0.933333333333333 1" />
      </material>
    </visual>
    <collision>
      <origin
        xyz="0 0 0"
        rpy="0 0 0" />
      <geometry>
        <mesh
          filename="package://Robot_collision/meshes/neck_Link.STL" />
      </geometry>
    </collision>
  </link>
  <joint
    name="neck_joint"
    type="revolute">
    <origin
      xyz="0.048815 0.38675 0.061874"
      rpy="3.1416 0 3.1416" />
    <parent
      link="base_link" />
    <child
      link="neck_Link" />
    <axis
      xyz="0 -1 0" />
    <limit
      lower="0"
      upper="3.142"
      effort="0.505"
      velocity="8.72" />
  </joint>
</robot>