<?xml version="1.0" encoding="utf-8"?>
<!-- This URDF was automatically created by SolidWorks to URDF Exporter! Originally created by Stephen Brawner (brawner@gmail.com) 
     Commit Version: 1.6.0-4-g7f85cfe  Build Version: 1.6.7995.38578
     For more information, please see http://wiki.ros.org/sw_urdf_exporter -->
<robot
  name="Robot_visual">
  <link
    name="base_link">
    <inertial>
      <origin
        xyz="0.0401810060046799 0.331786579487754 0.0352959668076187"
        rpy="0 0 0" />
      <mass
        value="0.150576513646478" />
      <inertia
        ixx="0.000108130795364864"
        ixy="-2.46379353815347E-20"
        ixz="7.96943004616914E-08"
        iyy="0.000192562652313604"
        iyz="-1.89390776232506E-19"
        izz="0.000181703429676107" />
    </inertial>
    <visual>
      <origin
        xyz="0 0 0"
        rpy="0 0 0" />
      <geometry>
        <mesh
          filename="package://Robot_visual/meshes/base_link.STL" />
      </geometry>
      <material
        name="">
        <color
          rgba="0.752941176470588 0.752941176470588 0.752941176470588 1" />
      </material>
    </visual>
    <collision>
      <origin
        xyz="0 0 0"
        rpy="0 0 0" />
      <geometry>
        <mesh
          filename="package://Robot_visual/meshes/base_link.STL" />
      </geometry>
    </collision>
  </link>
  <link
    name="hip_Link">
    <inertial>
      <origin
        xyz="0.000375231678648277 0.0220774190461577 0.00781561832095265"
        rpy="0 0 0" />
      <mass
        value="0.0406255317489471" />
      <inertia
        ixx="9.80786300584941E-06"
        ixy="-3.03552295829515E-22"
        ixz="-9.71909955561927E-10"
        iyy="6.43716459709308E-06"
        iyz="-5.23453333357324E-08"
        izz="6.33819448840706E-06" />
    </inertial>
    <visual>
      <origin
        xyz="0 0 0"
        rpy="0 0 0" />
      <geometry>
        <mesh
          filename="package://Robot_visual/meshes/hip_Link.STL" />
      </geometry>
      <material
        name="">
        <color
          rgba="0.752941176470588 0.752941176470588 0.752941176470588 1" />
      </material>
    </visual>
    <collision>
      <origin
        xyz="0 0 0"
        rpy="0 0 0" />
      <geometry>
        <mesh
          filename="package://Robot_visual/meshes/hip_Link.STL" />
      </geometry>
    </collision>
  </link>
  <joint
    name="hip_joint"
    type="revolute">
    <origin
      xyz="0.0026505 0.24245 0.025446"
      rpy="0 0 0" />
    <parent
      link="base_link" />
    <child
      link="hip_Link" />
    <axis
      xyz="0 1 0" />
    <limit
      lower="0"
      upper="3.14"
      effort="0.505"
      velocity="8.72" />
  </joint>
  <link
    name="thigh_Link">
    <inertial>
      <origin
        xyz="0.0253254685287808 -0.0180431075131695 7.81312186782721E-06"
        rpy="0 0 0" />
      <mass
        value="0.0474577407114944" />
      <inertia
        ixx="8.66835175137434E-06"
        ixy="-5.23453333357292E-08"
        ixz="-1.06872484518158E-10"
        iyy="6.98674583183773E-06"
        iyz="8.25183020102476E-11"
        izz="1.22212930303417E-05" />
    </inertial>
    <visual>
      <origin
        xyz="0 0 0"
        rpy="0 0 0" />
      <geometry>
        <mesh
          filename="package://Robot_visual/meshes/thigh_Link.STL" />
      </geometry>
      <material
        name="">
        <color
          rgba="0.752941176470588 0.752941176470588 0.752941176470588 1" />
      </material>
    </visual>
    <collision>
      <origin
        xyz="0 0 0"
        rpy="0 0 0" />
      <geometry>
        <mesh
          filename="package://Robot_visual/meshes/thigh_Link.STL" />
      </geometry>
    </collision>
  </link>
  <joint
    name="thigh_joint"
    type="revolute">
    <origin
      xyz="-0.019363 -0.02734 1.8014E-05"
      rpy="0 0 0" />
    <parent
      link="hip_Link" />
    <child
      link="thigh_Link" />
    <axis
      xyz="1 0 0" />
    <limit
      lower="0"
      upper="1.047"
      effort="0.505"
      velocity="8.72" />
  </joint>
  <link
    name="leg_Link">
    <inertial>
      <origin
        xyz="-0.0285390710342944 -0.0126064105119781 0.00485979795787559"
        rpy="0 0 0" />
      <mass
        value="0.0582940636416205" />
      <inertia
        ixx="2.72770431978539E-05"
        ixy="5.23415177903817E-08"
        ixz="2.01305685819592E-13"
        iyy="8.82495379340482E-06"
        iyz="-9.64680350901821E-07"
        izz="2.9839846600908E-05" />
    </inertial>
    <visual>
      <origin
        xyz="0 0 0"
        rpy="0 0 0" />
      <geometry>
        <mesh
          filename="package://Robot_visual/meshes/leg_Link.STL" />
      </geometry>
      <material
        name="">
        <color
          rgba="0.752941176470588 0.752941176470588 0.752941176470588 1" />
      </material>
    </visual>
    <collision>
      <origin
        xyz="0 0 0"
        rpy="0 0 0" />
      <geometry>
        <mesh
          filename="package://Robot_visual/meshes/leg_Link.STL" />
      </geometry>
    </collision>
  </link>
  <joint
    name="leg_joint"
    type="revolute">
    <origin
      xyz="0.054 -0.09411 3.5486E-05"
      rpy="0 0 0" />
    <parent
      link="thigh_Link" />
    <child
      link="leg_Link" />
    <axis
      xyz="1 0 0" />
    <limit
      lower="0"
      upper="1.047"
      effort="0.505"
      velocity="8.72" />
  </joint>
  <link
    name="foot1Link">
    <inertial>
      <origin
        xyz="-0.0264476634523562 -0.00503739187076357 0.00815571818852375"
        rpy="0 0 0" />
      <mass
        value="0.0535012177122182" />
      <inertia
        ixx="2.06588045150592E-05"
        ixy="5.19624692095533E-08"
        ixz="2.99656855482002E-08"
        iyy="2.67845482317156E-05"
        iyz="3.96121664948847E-22"
        izz="1.54972909145E-05" />
    </inertial>
    <visual>
      <origin
        xyz="0 0 0"
        rpy="0 0 0" />
      <geometry>
        <mesh
          filename="package://Robot_visual/meshes/foot1Link.STL" />
      </geometry>
      <material
        name="">
        <color
          rgba="0.752941176470588 0.752941176470588 0.752941176470588 1" />
      </material>
    </visual>
    <collision>
      <origin
        xyz="0 0 0"
        rpy="0 0 0" />
      <geometry>
        <mesh
          filename="package://Robot_visual/meshes/foot1Link.STL" />
      </geometry>
    </collision>
  </link>
  <joint
    name="foot1_joint"
    type="revolute">
    <origin
      xyz="0 -0.093 0"
      rpy="0 0 0" />
    <parent
      link="leg_Link" />
    <child
      link="foot1Link" />
    <axis
      xyz="1 0 0" />
    <limit
      lower="0"
      upper="0.523"
      effort="0.505"
      velocity="8.72" />
  </joint>
  <link
    name="foot2_Link">
    <inertial>
      <origin
        xyz="-2.5853164262955E-05 0.00566057052955886 -0.0216512687907475"
        rpy="0 0 0" />
      <mass
        value="0.0372088933681426" />
      <inertia
        ixx="9.6735685377817E-06"
        ixy="-3.82864126172109E-10"
        ixz="-4.26964685275401E-21"
        iyy="6.36833977773333E-06"
        iyz="5.2345333335728E-08"
        izz="5.99785017877914E-06" />
    </inertial>
    <visual>
      <origin
        xyz="0 0 0"
        rpy="0 0 0" />
      <geometry>
        <mesh
          filename="package://Robot_visual/meshes/foot2_Link.STL" />
      </geometry>
      <material
        name="">
        <color
          rgba="0.752941176470588 0.752941176470588 0.752941176470588 1" />
      </material>
    </visual>
    <collision>
      <origin
        xyz="0 0 0"
        rpy="0 0 0" />
      <geometry>
        <mesh
          filename="package://Robot_visual/meshes/foot2_Link.STL" />
      </geometry>
    </collision>
  </link>
  <joint
    name="foot2_joint"
    type="revolute">
    <origin
      xyz="-0.024645 -0.093 -0.0205"
      rpy="0 0 0" />
    <parent
      link="leg_Link" />
    <child
      link="foot2_Link" />
    <axis
      xyz="0 0 1" />
    <limit
      lower="0"
      upper="3.14"
      effort="0.505"
      velocity="8.72" />
  </joint>
  <link
    name="hip2_Link">
    <inertial>
      <origin
        xyz="0.000375231679004905 0.019077419046091 0.00781561832095055"
        rpy="0 0 0" />
      <mass
        value="0.0812510634978942" />
      <inertia
        ixx="1.96157260116988E-05"
        ixy="-1.23915022988868E-21"
        ixz="-1.94381991112374E-09"
        iyy="1.28743291941862E-05"
        iyz="-1.04690666671465E-07"
        izz="1.26763889768141E-05" />
    </inertial>
    <visual>
      <origin
        xyz="0 0 0"
        rpy="0 0 0" />
      <geometry>
        <mesh
          filename="package://Robot_visual/meshes/hip2_Link.STL" />
      </geometry>
      <material
        name="">
        <color
          rgba="0.752941176470588 0.752941176470588 0.752941176470588 1" />
      </material>
    </visual>
    <collision>
      <origin
        xyz="0 0 0"
        rpy="0 0 0" />
      <geometry>
        <mesh
          filename="package://Robot_visual/meshes/hip2_Link.STL" />
      </geometry>
    </collision>
  </link>
  <joint
    name="hip2_joint"
    type="revolute">
    <origin
      xyz="0.077751 0.24545 0.025446"
      rpy="0 0 0" />
    <parent
      link="base_link" />
    <child
      link="hip2_Link" />
    <axis
      xyz="0 1 0" />
    <limit
      lower="0"
      upper="3.142"
      effort="0.505"
      velocity="8.72" />
  </joint>
  <link
    name="thigh2_Link">
    <inertial>
      <origin
        xyz="-0.0342620709334726 0.049417419046091 0.00779760382796379"
        rpy="0 0 0" />
      <mass
        value="0.0812510634978942" />
      <inertia
        ixx="1.96157260116988E-05"
        ixy="-1.22807918596397E-21"
        ixz="-1.94381991112374E-09"
        iyy="1.28743291941862E-05"
        iyz="-1.04690666671465E-07"
        izz="1.26763889768141E-05" />
    </inertial>
    <visual>
      <origin
        xyz="0 0 0"
        rpy="0 0 0" />
      <geometry>
        <mesh
          filename="package://Robot_visual/meshes/thigh2_Link.STL" />
      </geometry>
      <material
        name="">
        <color
          rgba="0.752941176470588 0.752941176470588 0.752941176470588 1" />
      </material>
    </visual>
    <collision>
      <origin
        xyz="0 0 0"
        rpy="0 0 0" />
      <geometry>
        <mesh
          filename="package://Robot_visual/meshes/thigh2_Link.STL" />
      </geometry>
    </collision>
  </link>
  <joint
    name="thigh2_joint"
    type="revolute">
    <origin
      xyz="0.034637 -0.03034 1.8014E-05"
      rpy="0 0 0" />
    <parent
      link="hip2_Link" />
    <child
      link="thigh2_Link" />
    <axis
      xyz="1 0 0" />
    <limit
      lower="0"
      upper="1.04"
      effort="0.505"
      velocity="8.72" />
  </joint>
  <link
    name="leg2_Link">
    <inertial>
      <origin
        xyz="-0.0285165850182353 -0.0110288911479769 0.00388806846756112"
        rpy="0 0 0" />
      <mass
        value="0.111277328855263" />
      <inertia
        ixx="5.37565328428597E-05"
        ixy="1.04683042764819E-07"
        ixz="5.3336212480671E-13"
        iyy="1.62595313750558E-05"
        iyz="-1.34271492398453E-06"
        izz="5.75380896642682E-05" />
    </inertial>
    <visual>
      <origin
        xyz="0 0 0"
        rpy="0 0 0" />
      <geometry>
        <mesh
          filename="package://Robot_visual/meshes/leg2_Link.STL" />
      </geometry>
      <material
        name="">
        <color
          rgba="0.752941176470588 0.752941176470588 0.752941176470588 1" />
      </material>
    </visual>
    <collision>
      <origin
        xyz="0 0 0"
        rpy="0 0 0" />
      <geometry>
        <mesh
          filename="package://Robot_visual/meshes/leg2_Link.STL" />
      </geometry>
    </collision>
  </link>
  <joint
    name="leg2_joint"
    type="revolute">
    <origin
      xyz="0 -0.09411 3.5486E-05"
      rpy="0 0 0" />
    <parent
      link="thigh2_Link" />
    <child
      link="leg2_Link" />
    <axis
      xyz="-1 0 0" />
    <limit
      lower="0"
      upper="0.523"
      effort="0.505"
      velocity="8.72" />
  </joint>
  <link
    name="foot3_Link">
    <inertial>
      <origin
        xyz="-0.026447663451981 -0.00503739187082926 0.0081557181885232"
        rpy="0 0 0" />
      <mass
        value="0.0535012177122182" />
      <inertia
        ixx="2.06588045150592E-05"
        ixy="5.19624692095534E-08"
        ixz="2.99656855482004E-08"
        iyy="2.67845482317156E-05"
        iyz="4.06824048578485E-22"
        izz="1.54972909145E-05" />
    </inertial>
    <visual>
      <origin
        xyz="0 0 0"
        rpy="0 0 0" />
      <geometry>
        <mesh
          filename="package://Robot_visual/meshes/foot3_Link.STL" />
      </geometry>
      <material
        name="">
        <color
          rgba="0.752941176470588 0.752941176470588 0.752941176470588 1" />
      </material>
    </visual>
    <collision>
      <origin
        xyz="0 0 0"
        rpy="0 0 0" />
      <geometry>
        <mesh
          filename="package://Robot_visual/meshes/foot3_Link.STL" />
      </geometry>
    </collision>
  </link>
  <joint
    name="foot3_joint"
    type="revolute">
    <origin
      xyz="0 -0.092986 0.001587"
      rpy="0 0 0" />
    <parent
      link="leg2_Link" />
    <child
      link="foot3_Link" />
    <axis
      xyz="1 0 0" />
    <limit
      lower="0"
      upper="0.523"
      effort="0.505"
      velocity="8.72" />
  </joint>
  <link
    name="foot4_Link">
    <inertial>
      <origin
        xyz="-2.58531638877152E-05 0.00566057052949243 -0.0216512687907491"
        rpy="0 0 0" />
      <mass
        value="0.0372088933681426" />
      <inertia
        ixx="9.6735685377817E-06"
        ixy="-3.82864126180089E-10"
        ixz="-8.28829927605747E-22"
        iyy="6.36833977773332E-06"
        iyz="5.23453333357268E-08"
        izz="5.99785017877913E-06" />
    </inertial>
    <visual>
      <origin
        xyz="0 0 0"
        rpy="0 0 0" />
      <geometry>
        <mesh
          filename="package://Robot_visual/meshes/foot4_Link.STL" />
      </geometry>
      <material
        name="">
        <color
          rgba="0.752941176470588 0.752941176470588 0.752941176470588 1" />
      </material>
    </visual>
    <collision>
      <origin
        xyz="0 0 0"
        rpy="0 0 0" />
      <geometry>
        <mesh
          filename="package://Robot_visual/meshes/foot4_Link.STL" />
      </geometry>
    </collision>
  </link>
  <joint
    name="foot4_joint"
    type="revolute">
    <origin
      xyz="-0.024645 -0.092986 -0.018913"
      rpy="0 0 0" />
    <parent
      link="leg2_Link" />
    <child
      link="foot4_Link" />
    <axis
      xyz="0 0 -1" />
    <limit
      lower="0"
      upper="3.14"
      effort="0.505"
      velocity="8.72" />
  </joint>
  <link
    name="neck_Link">
    <inertial>
      <origin
        xyz="-0.0114350675543291 0.0298274611173384 -0.0147167215824987"
        rpy="0 0 0" />
      <mass
        value="0.0535113637048835" />
      <inertia
        ixx="7.73004737504562E-06"
        ixy="-1.32510352644368E-08"
        ixz="1.90610291175162E-08"
        iyy="2.33892662961815E-05"
        iyz="2.34093466656608E-06"
        izz="2.68027256486278E-05" />
    </inertial>
    <visual>
      <origin
        xyz="0 0 0"
        rpy="0 0 0" />
      <geometry>
        <mesh
          filename="package://Robot_visual/meshes/neck_Link.STL" />
      </geometry>
      <material
        name="">
        <color
          rgba="0.752941176470588 0.752941176470588 0.752941176470588 1" />
      </material>
    </visual>
    <collision>
      <origin
        xyz="0 0 0"
        rpy="0 0 0" />
      <geometry>
        <mesh
          filename="package://Robot_visual/meshes/neck_Link.STL" />
      </geometry>
    </collision>
  </link>
  <joint
    name="neck_joint"
    type="revolute">
    <origin
      xyz="0.048815 0.38675 0.061874"
      rpy="3.1416 0 3.1416" />
    <parent
      link="base_link" />
    <child
      link="neck_Link" />
    <axis
      xyz="0 -1 0" />
    <limit
      lower="0"
      upper="3.14"
      effort="0.505"
      velocity="8.72" />
  </joint>
</robot>